Workbook

Sheet BAUCHER 2026
A1: Concepto | B1: Nombre del cliente | C1: Servicio | D1: Feha Solicitud | E1: Fecha estimada de entrega | F1: Fecha de pago | G1: Monto en cordobas | H1: Estado | I1: Fecha registro | K1: Buscar por concepto | M1: Buscar bauchcer
A2: T-4CGUCZ | B2: RAFAEL DE LOS ANGELES MARENCO CANALES | C2: APROVACION Y REVICIÓN DE PLANOS TOPOGRAFICOS CON FINES CATASTRALES | D2: 46036 | E2: 46057 | F2: 46036 | G2: 1510 | H2: Espera | I2: =TEXT(D2,"mmmm") -> enero | M2: T-4CHFO9
A3: T-4CHCQJ | B3: MILTON JAVIER ZAVALA | C3: APROVACION Y REVICIÓN DE PLANOS TOPOGRAFICOS CON FINES CATASTRALES | D3: 46049 | E3: 46070 | F3: 46049 | G3: 1510 | H3: Entregado | I3: =TEXT(D3,"mmmm") -> enero
A4: T-4CHAC9 | B4: BEATRIZ ELAINE VERDE GARCIA | C4: APROVACION Y REVICIÓN DE PLANOS TOPOGRAFICOS CON FINES CATASTRALES | D4: 46048 | E4: 46069 | F4: 46048 | G4: 1510 | H4: Entregado | I4: =TEXT(D4,"mmmm") -> enero
A5: T-4CH2CX | B5: JOSE FRANCISCO ZAMBRANA CORDOBA | C5: APROVACION Y REVICIÓN DE PLANOS TOPOGRAFICOS CON FINES CATASTRALES | D5: 46042 | E5: 46063 | F5: 46042 | G5: 1510 | H5: Entregado | I5: =TEXT(D5,"mmmm") -> enero
A6: T-4CH2BY | B6: JUDITH SALVADORA REYES OROZCO | C6: APROVACION Y REVICIÓN DE PLANOS TOPOGRAFICOS CON FINES CATASTRALES | D6: 46042 | E6: 46063 | F6: 46042 | G6: 1510 | H6: Espera | I6: =TEXT(D6,"mmmm") -> enero
A7: T-4CH2D7 | B7: JOEL FERNANDO LARA MIRANDA | C7: APROVACION Y REVICIÓN DE PLANOS TOPOGRAFICOS CON FINES CATASTRALES | D7: 46042 | E7: 46063 | F7: 46042 | G7: 1510 | H7: Entregado | I7: =TEXT(D7,"mmmm") -> enero
A8: T-4CH2CB | B8: YURI ELIETH BROWN GONZALES | C8: APROVACION Y REVICIÓN DE PLANOS TOPOGRAFICOS CON FINES CATASTRALES | D8: 46042 | E8: 46063 | F8: 46042 | G8: 1510 | H8: Espera | I8: =TEXT(D8,"mmmm") -> enero
A9: T-4CHCPI | B9: MILTON JAVIER ZAVALA | C9: APROVACION Y REVICIÓN DE PLANOS TOPOGRAFICOS CON FINES CATASTRALES | D9: 46049 | E9: 46070 | F9: 46049 | G9: 1510 | H9: Entregado | I9: =TEXT(D9,"mmmm") -> enero
A10: T-4CHFNK | B10: IVANIA DEL CARMEN CASTILLO MEZA | C10: APROVACION Y REVICIÓN DE PLANOS TOPOGRAFICOS CON FINES CATASTRALES | D10: 46050 | E10: 46072 | F10: 46050 | G10: 1510 | H10: Espera | I10: =TEXT(D10,"mmmm") -> enero
A11: T-4CHFO9 | B11: LIGIA DEL SOCORRO CASTILLO MEZA | C11: APROVACION Y REVICIÓN DE PLANOS TOPOGRAFICOS CON FINES CATASTRALES | D11: 46050 | E11: 46072 | F11: 46050 | G11: 1510 | H11: Espera | I11: =TEXT(D11,"mmmm") -> enero
A12: T-4CHFOP | B12: GLORIA ELENA CASTILLO MEZA | C12: APROVACION Y REVICIÓN DE PLANOS TOPOGRAFICOS CON FINES CATASTRALES | D12: 46050 | E12: 46072 | F12: 46081 | G12: 1510 | H12: Espera | I12: =TEXT(D12,"mmmm") -> enero
A13: T-4CH6LX | B13: MIGUEL ANGEL ABEA BRAVO | C13: APROVACION Y REVICIÓN DE PLANOS TOPOGRAFICOS CON FINES CATASTRALES | D13: 46044 | E13: 46065 | F13: 46044 | G13: 1510 | H13: Espera | I13: =TEXT(D13,"mmmm") -> enero
A14: T-4CGUC2 | B14: OMAR FRANCISCO MARTINEZ SILVA | C14: APROVACION Y REVICIÓN DE PLANOS TOPOGRAFICOS CON FINES CATASTRALES | D14: 46036 | E14: 46057 | F14: 46036 | G14: 1510 | H14: Espera | I14: =TEXT(D14,"mmmm") -> enero
... A34: T-4CHZ2L | B34: HUGO LEONEL MORALES MUÑOZ | C34: APROVACION Y REVICIÓN DE PLANOS TOPOGRAFICOS CON FINES CATASTRALES | D34: 46064 | E34: 46085 | F34: 46064 | G34: 2510 | H34: Espera | I34: =TEXT(D34,"mmmm") -> febrero
A35: T-4CHWMB | B35: IUAN MARIA OSORNO VILLATORO | C35: APROVACION Y REVICIÓN DE PLANOS TOPOGRAFICOS CON FINES CATASTRALES | D35: 46063 | E35: 03/032026 | F35: 46063 | G35: 8000 | H35: Entregado | I35: =TEXT(D35,"mmmm") -> febrero
A36: T-4CI7KI | B36: WALMER JOSE TERCERO MONTOYA | C36: APROVACION Y REVICIÓN DE PLANOS TOPOGRAFICOS CON FINES CATASTRALES | D36: 46070 | E36: 46091 | F36: 46070 | G36: 1510 | H36: Entregado | I36: =TEXT(D36,"mmmm") -> febrero
A37: T-4CI5SV | B37: JAVIER HERNANDEZ RUIZ | C37: APROVACION Y REVICIÓN DE PLANOS TOPOGRAFICOS CON FINES CATASTRALES | D37: 46069 | E37: 46090 | F37: 46069 | G37: 1510 | H37: Espera | I37: =TEXT(D37,"mmmm") -> febrero
A38: T-4CI5S9 | B38: JOSEFA DEL CARMEN VASQUEZ VEGA | C38: APROVACION Y REVICIÓN DE PLANOS TOPOGRAFICOS CON FINES CATASTRALES | D38: 46069 | E38: 46090 | F38: 46069 | G38: 1510 | H38: Suspendido | I38: =TEXT(D38,"mmmm") -> febrero
A39: T-4CI3IT | B39: RAUL ERNESTO CHAMORRO GONZALES | C39: APROVACION Y REVICIÓN DE PLANOS TOPOGRAFICOS CON FINES CATASTRALES | D39: 46066 | E39: 46087 | F39: 46066 | G39: 1510 | H39: Entregado | I39: =TEXT(D39,"mmmm") -> febrero
A40: T-4CIDFS | B40: BENJAMIN MATHIAS MICHAEL HASS | C40: APROVACION Y REVICIÓN DE PLANOS TOPOGRAFICOS CON FINES CATASTRALES | D40: 46073 | E40: 46094 | F40: 46073 | G40: 1510 | H40: Aprovados | I40: =TEXT(D40,"mmmm") -> febrero
A41: T-4CI9GU | B41: JOSE ANGEL MAYORGA Y OTROS | C41: APROVACION Y REVICIÓN DE PLANOS TOPOGRAFICOS CON FINES CATASTRALES | D41: 46071 | E41: 46092 | F41: 46071 | G41: 1510 | H41: Suspendido | I41: =TEXT(D41,"mmmm") -> febrero
A42: T-4CI3IT | B42: RAUL ERNESTO CHAMORRO GONZALES | C42: APROVACION Y REVICIÓN DE PLANOS TOPOGRAFICOS CON FINES CATASTRALES | D42: 46066 | E42: 46087 | F42: 46066 | G42: 1510 | H42: Entregado | I42: =TEXT(D42,"mmmm") -> febrero
A43: T-4CIPB6 | B43: MILTON ANDRES CRUZ NICARAGUA | C43: APROVACION Y REVICIÓN DE PLANOS TOPOGRAFICOS CON FINES CATASTRALES | D43: 46080 | E43: 46101 | F43: 46080 | G43: 1510 | H43: Espera | I43: =TEXT(D43,"mmmm") -> febrero
A44: T-4CIPC3 | B44: LIDIA DEL SOCORRO PEREZ BRIONES | C44: APROVACION Y REVICIÓN DE PLANOS TOPOGRAFICOS CON FINES CATASTRALES | D44: 46080 | E44: 46101 | F44: 46080 | G44: 1510 | H44: Espera | I44: =TEXT(D44,"mmmm") -> febrero
A45: T-4CI3L3 | B45: CARMEN CECILIA FLORES GUTIERREZ | C45: APROVACION Y REVICIÓN DE PLANOS TOPOGRAFICOS CON FINES CATASTRALES | D45: 46066 | E45: 46087 | F45: 46066 | G45: 1510 | H45: Aprovados | I45: =TEXT(D45,"mmmm") -> febrero
A46: T-4CIILR | B46: LILLIAM DEL CARMEN PEREZ LOPEZ | C46: APROVACION Y REVICIÓN DE PLANOS TOPOGRAFICOS CON FINES CATASTRALES | D46: 46077 | E46: 46098 | F46: 46077 | G46: 1510 | H46: Espera | I46: =TEXT(D46,"mmmm") -> febrero
A47: T-4CLI9I | B47: ROSA ESMERALDA CASTILLO CASTRO | C47: APROVACION Y REVICIÓN DE PLANOS TOPOGRAFICOS CON FINES CATASTRALES | D47: 46078 | E47: 46099 | F47: 46078 | G47: 1510 | H47: Espera | I47: =TEXT(D47,"mmmm") -> febrero
... A51: T-4CILBE | B51: GREGORY HERNANDEZ | C51: APROVACION Y REVICIÓN DE PLANOS TOPOGRAFICOS CON FINES CATASTRALES | D51: 46078 | E51: 46099 | F51: 46078 | G51: 1510 | H51: Aprovados | I51: =TEXT(D51,"mmmm") -> febrero
I52: =TEXT(D52,"mmmm") -> enero
I53: =TEXT(D53,"mmmm") -> enero
I54: =TEXT(D54,"mmmm") -> enero
I55: =TEXT(D55,"mmmm") -> enero
I56: =TEXT(D56,"mmmm") -> enero
I57: =TEXT(D57,"mmmm") -> enero
I58: =TEXT(D58,"mmmm") -> enero
I59: =TEXT(D59,"mmmm") -> enero
I60: =TEXT(D60,"mmmm") -> enero
I61: =TEXT(D61,"mmmm") -> enero
I62: =TEXT(D62,"mmmm") -> enero
...

Sheet Consultas
C2: CONSULTAS
C3: Concepto | D3: Nombre cliente | E3: Servicio | F3: Fecha solicitud | G3: Fecha estimada de entrega | H3: Fecha de pago | I3: Monto en cordoba | J3: Estado | K3: Fecha registro
C4: {=_xlfn._xlws.FILTER(TablaDatos[],TablaDatos[Nombre del cliente]="BOSCO ROBERTO ZAMPIERI MORALES ","No hay registro")} -> T-4CHZ1Y | D4: BOSCO ROBERTO ZAMPIERI MORALES | E4: APROVACION Y REVICIÓN DE PLANOS TOPOGRAFICOS CON FINES CATASTRALES | F4: 46064 | G4: 46085 | H4: 46064 | I4: 1510 | J4: Entregado | K4: febrero
B6: control de codigos
B7: Codigo | C7: Concepto | D7: Nombre cliente | E7: Servicio | F7: Fecha solicitud | G7: Fecha estimada de entrega | H7: Fecha de pago | I7: Monto en cordoba | J7: Estado | K7: Fecha registro
B8: T-4CI3L3 | C8: {=_xlfn._xlws.FILTER('BAUCHER 2026'!A2:I1000, 'BAUCHER 2026'!A2:A1000 = B8, "No hay datos para este conceptoo ")} -> T-4CI3L3 | D8: CARMEN CECILIA FLORES GUTIERREZ | E8: APROVACION Y REVICIÓN DE PLANOS TOPOGRAFICOS CON FINES CATASTRALES | F8: 46066 | G8: 46087 | H8: 46066 | I8: 1510 | J8: Aprovados | K8: febrero
B12: control de fechas por solicitud
B13: Fecha | C13: Concepto | D13: Nombre cliente | E13: Servicio | F13: Fecha solicitud | G13: Fecha estimada de entrega | H13: Fecha de pago | I13: Monto en cordoba | J13: Estado | K13: fecha registr
B14: 46044 | C14: {=_xlfn._xlws.FILTER('BAUCHER 2026'!A2:I1000, 'BAUCHER 2026'!D2:D1000 = B14, "No hay datos para esta fecha")} -> T-4CH6LX | D14: MIGUEL ANGEL ABEA BRAVO | E14: APROVACION Y REVICIÓN DE PLANOS TOPOGRAFICOS CON FINES CATASTRALES | F14: 46044 | G14: 46065 | H14: 46044 | I14: 1510 | J14: Espera | K14: enero
B18: control de fechas por Estimacion de entrega
B19: Fecha | C19: Concepto | D19: Nombre cliente | E19: Servicio | F19: Fecha solicitud | G19: Fecha estimada de entrega | H19: Fecha de pago | I19: Monto en cordoba | J19: Estado | K19: Fecha Registro
B20: 46070 | C20: {=_xlfn._xlws.FILTER('BAUCHER 2026'!A2:I1000, 'BAUCHER 2026'!E2:E1000= B20, "No hay datos para esta fecha")} -> T-4CHCQJ | D20: MILTON JAVIER ZAVALA | E20: APROVACION Y REVICIÓN DE PLANOS TOPOGRAFICOS CON FINES CATASTRALES | F20: 46049 | G20: 46070 | H20: 46049 | I20: 1510 | J20: Entregado | K20: enero
C21: T-4CHCPI | D21: MILTON JAVIER ZAVALA | E21: APROVACION Y REVICIÓN DE PLANOS TOPOGRAFICOS CON FINES CATASTRALES | F21: 46049 | G21: 46070 | H21: 46049 | I21: 1510 | J21: Entregado | K21: enero
C22: T-4CHCQK | D22: DIONICIO CUADRA KAUTZ | E22: APROVACION Y REVICIÓN DE PLANOS TOPOGRAFICOS CON FINES CATASTRALES | F22: 46049 | G22: 46070 | H22: 46049 | I22: 1510 | J22: Aprovados | K22: enero
C23: T-4CHCQ0 | D23: DIONICIO CUADRA KAUTZ | E23: APROVACION Y REVICIÓN DE PLANOS TOPOGRAFICOS CON FINES CATASTRALES | F23: 46049 | G23: 46070 | H23: 46049 | I23: 1510 | J23: Aprovados | K23: enero
B26: control de fechas por pagos
B27: Fecha | C27: Concepto | D27: Nombre cliente | E27: Servicio | F27: Fecha solicitud | G27: Fecha estimada de entrega | H27: Fecha de pago | I27: Monto en cordoba | J27: Estado | K27: fecha registro
B28: 46043 | C28: {=_xlfn._xlws.FILTER('BAUCHER 2026'!A2:I1000, 'BAUCHER 2026'!F2:F1000= B28, "No hay datos para esta fecha")} -> T-4CH4KD | D28: MARIA DE JESUS GONZALES GUADAMUZ | E28: APROVACION Y REVICIÓN DE PLANOS TOPOGRAFICOS CON FINES CATASTRALES | F28: 46043 | G28: 46064 | H28: 46043 | I28: 1510 | J28: Espera | K28: enero
C29: T-4CH4LJ | D29: GEORGE THOMAS HAMILTON | E29: APROVACION Y REVICIÓN DE PLANOS TOPOGRAFICOS CON FINES CATASTRALES | F29: 46043 | G29: 46064 | H29: 46043 | I29: 1510 | J29: Espera | K29: enero
C30: T-4CH4KT | D30: GIOVANIA AUXILIADORA WELLINGSTON ALFONSO | E30: APROVACION Y REVICIÓN DE PLANOS TOPOGRAFICOS CON FINES CATASTRALES | F30: 46043 | G30: 46064 | H30: 46043 | I30: 1510 | J30: Espera | K30: enero
C31: T-4CH4JR | D31: ANA LOPEZ BERMUDEZ | E31: APROVACION Y REVICIÓN DE PLANOS TOPOGRAFICOS CON FINES CATASTRALES | F31: 46043 | G31: 46064 | H31: 46043 | I31: 1510 | J31: Espera | K31: enero
B34: Control de estados
B35: Estado | C35: Concepto | D35: Nombre cliente | E35: Servicio | F35: Fecha solicitud | G35: Fecha estimada de entrega | H35: Fecha de pago | I35: Monto en cordoba | J35: Estado | K35: Fecha registro
B36: aprovados | C36: {=_xlfn._xlws.FILTER('BAUCHER 2026'!A2:I1000, 'BAUCHER 2026'!H2:H1000= B36, "No hay registros")} -> T-4CHCQK | D36: DIONICIO CUADRA KAUTZ | E36: APROVACION Y REVICIÓN DE PLANOS TOPOGRAFICOS CON FINES CATASTRALES | F36: 46049 | G36: 46070 | H36: 46049 | I36: 1510 | J36: Aprovados | K36: enero
C37: T-4CHCQ0 | D37: DIONICIO CUADRA KAUTZ | E37: APROVACION Y REVICIÓN DE PLANOS TOPOGRAFICOS CON FINES CATASTRALES | F37: 46049 | G37: 46070 | H37: 46049 | I37: 1510 | J37: Aprovados | K37: enero
C38: T-4CIDFS | D38: BENJAMIN MATHIAS MICHAEL HASS | E38: APROVACION Y REVICIÓN DE PLANOS TOPOGRAFICOS CON FINES CATASTRALES | F38: 46073 | G38: 46094 | H38: 46073 | I38: 1510 | J38: Aprovados | K38: febrero
C39: T-4CI3L3 | D39: CARMEN CECILIA FLORES GUTIERREZ | E39: APROVACION Y REVICIÓN DE PLANOS TOPOGRAFICOS CON FINES CATASTRALES | F39: 46066 | G39: 46087 | H39: 46066 | I39: 1510 | J39: Aprovados | K39: febrero
C40: T-4CILAP | D40: GREGORY HERNANDEZ | E40: APROVACION Y REVICIÓN DE PLANOS TOPOGRAFICOS CON FINES CATASTRALES | F40: 46078 | G40: 46099 | H40: 46078 | I40: 1510 | J40: Aprovados | K40: febrero
C41: T-4CILBE | D41: GREGORY HERNANDEZ | E41: APROVACION Y REVICIÓN DE PLANOS TOPOGRAFICOS CON FINES CATASTRALES | F41: 46078 | G41: 46099 | H41: 46078 | I41: 1510 | J41: Aprovados | K41: febrero
